<mujoco model="g1_12dof">
  <compiler angle="radian" meshdir="meshes/"/>

  <statistic meansize="0.144785" extent="1.23314" center="0.025392 2.0634e-05 -0.245975"/>
  <default>
    <joint damping="0.001" armature="0.01" frictionloss="0.1"/>
  </default>

  <asset>
    <mesh name="pelvis" file="pelvis.STL"/>
    <mesh name="pelvis_contour_link" file="pelvis_contour_link.STL"/>
    <mesh name="left_hip_pitch_link" file="left_hip_pitch_link.STL"/>
    <mesh name="left_hip_roll_link" file="left_hip_roll_link.STL"/>
    <mesh name="left_hip_yaw_link" file="left_hip_yaw_link.STL"/>
    <mesh name="left_knee_link" file="left_knee_link.STL"/>
    <mesh name="left_ankle_pitch_link" file="left_ankle_pitch_link.STL"/>
    <mesh name="left_ankle_roll_link" file="left_ankle_roll_link.STL"/>
    <mesh name="right_hip_pitch_link" file="right_hip_pitch_link.STL"/>
    <mesh name="right_hip_roll_link" file="right_hip_roll_link.STL"/>
    <mesh name="right_hip_yaw_link" file="right_hip_yaw_link.STL"/>
    <mesh name="right_knee_link" file="right_knee_link.STL"/>
    <mesh name="right_ankle_pitch_link" file="right_ankle_pitch_link.STL"/>
    <mesh name="right_ankle_roll_link" file="right_ankle_roll_link.STL"/>
    <mesh name="torso_link_23dof_rev_1_0" file="torso_link_23dof_rev_1_0.STL"/>
    <mesh name="logo_link" file="logo_link.STL"/>
    <mesh name="head_link" file="head_link.STL"/>
    <mesh name="left_shoulder_pitch_link" file="left_shoulder_pitch_link.STL"/>
    <mesh name="left_shoulder_roll_link" file="left_shoulder_roll_link.STL"/>
    <mesh name="left_shoulder_yaw_link" file="left_shoulder_yaw_link.STL"/>
    <mesh name="left_elbow_link" file="left_elbow_link.STL"/>
    <mesh name="left_wrist_roll_rubber_hand" file="left_wrist_roll_rubber_hand.STL"/>
    <mesh name="right_shoulder_pitch_link" file="right_shoulder_pitch_link.STL"/>
    <mesh name="right_shoulder_roll_link" file="right_shoulder_roll_link.STL"/>
    <mesh name="right_shoulder_yaw_link" file="right_shoulder_yaw_link.STL"/>
    <mesh name="right_elbow_link" file="right_elbow_link.STL"/>
    <mesh name="right_wrist_roll_rubber_hand" file="right_wrist_roll_rubber_hand.STL"/>
    
    <!-- ЛЕВАЯ кисть -->
	<mesh name="left_wrist_roll_link"  file="left_wrist_roll_link.STL"/>
	<mesh name="left_wrist_pitch_link" file="left_wrist_pitch_link.STL"/>
	<mesh name="left_wrist_yaw_link"   file="left_wrist_yaw_link.STL"/>
	<mesh name="left_hand_palm_link"   file="left_hand_palm_link.STL"/>
	<mesh name="left_hand_thumb_0_link" file="left_hand_thumb_0_link.STL"/>
	<mesh name="left_hand_thumb_1_link" file="left_hand_thumb_1_link.STL"/>
	<mesh name="left_hand_thumb_2_link" file="left_hand_thumb_2_link.STL"/>
	<mesh name="left_hand_middle_0_link" file="left_hand_middle_0_link.STL"/>
	<mesh name="left_hand_middle_1_link" file="left_hand_middle_1_link.STL"/>
	<mesh name="left_hand_index_0_link"  file="left_hand_index_0_link.STL"/>
	<mesh name="left_hand_index_1_link"  file="left_hand_index_1_link.STL"/>

	<!-- ПРАВАЯ кисть -->
	<mesh name="right_wrist_roll_link"  file="right_wrist_roll_link.STL"/>
	<mesh name="right_wrist_pitch_link" file="right_wrist_pitch_link.STL"/>
	<mesh name="right_wrist_yaw_link"   file="right_wrist_yaw_link.STL"/>
	<mesh name="right_hand_palm_link"   file="right_hand_palm_link.STL"/>
	<mesh name="right_hand_thumb_0_link" file="right_hand_thumb_0_link.STL"/>
	<mesh name="right_hand_thumb_1_link" file="right_hand_thumb_1_link.STL"/>
	<mesh name="right_hand_thumb_2_link" file="right_hand_thumb_2_link.STL"/>
	<mesh name="right_hand_middle_0_link" file="right_hand_middle_0_link.STL"/>
	<mesh name="right_hand_middle_1_link" file="right_hand_middle_1_link.STL"/>
	<mesh name="right_hand_index_0_link"  file="right_hand_index_0_link.STL"/>
	<mesh name="right_hand_index_1_link"  file="right_hand_index_1_link.STL"/>

  </asset>

  <worldbody>
    <body name="pelvis" pos="0 0 0.793">
    <!-- Ноги — без изменений -->
      <body name="left_hip_pitch_link" pos="0 0.064452 -0.1027">
        <inertial pos="0.002741 0.047791 -0.02606" quat="0.954862 0.293964 0.0302556 0.030122" mass="1.35" diaginertia="0.00181517 0.00153422 0.00116212"/>
        <joint name="left_hip_pitch_joint" pos="0 0 0" axis="0 1 0" range="-2.5307 2.8798" actuatorfrcrange="-88 88"/>
        <geom type="mesh" contype="0" conaffinity="0" group="1" density="0" rgba="0.2 0.2 0.2 1" mesh="left_hip_pitch_link"/>
        <geom type="mesh" rgba="0.2 0.2 0.2 1" mesh="left_hip_pitch_link"/>
        <body name="left_hip_roll_link" pos="0 0.052 -0.030465" quat="0.996179 0 -0.0873386 0">
          <inertial pos="0.029812 -0.001045 -0.087934" quat="0.977808 -1.97119e-05 0.205576 -0.0403793" mass="1.52" diaginertia="0.00254986 0.00241169 0.00148755"/>
          <joint name="left_hip_roll_joint" pos="0 0 0" axis="1 0 0" range="-0.5236 2.9671" actuatorfrcrange="-139 139"/>
          <geom type="mesh" contype="0" conaffinity="0" group="1" density="0" rgba="0.7 0.7 0.7 1" mesh="left_hip_roll_link"/>
          <geom type="mesh" rgba="0.7 0.7 0.7 1" mesh="left_hip_roll_link"/>
          <body name="left_hip_yaw_link" pos="0.025001 0 -0.12412">
            <inertial pos="-0.057709 -0.010981 -0.15078" quat="0.600598 0.15832 0.223482 0.751181" mass="1.702" diaginertia="0.00776166 0.00717575 0.00160139"/>
            <joint name="left_hip_yaw_joint" pos="0 0 0" axis="0 0 1" range="-2.7576 2.7576" actuatorfrcrange="-88 88"/>
            <geom type="mesh" contype="0" conaffinity="0" group="1" density="0" rgba="0.7 0.7 0.7 1" mesh="left_hip_yaw_link"/>
            <geom type="mesh" rgba="0.7 0.7 0.7 1" mesh="left_hip_yaw_link"/>
            <body name="left_knee_link" pos="-0.078273 0.0021489 -0.17734" quat="0.996179 0 0.0873386 0">
              <inertial pos="0.005457 0.003964 -0.12074" quat="0.923418 -0.0327699 0.0158246 0.382067" mass="1.932" diaginertia="0.0113804 0.0112778 0.00146458"/>
              <joint name="left_knee_joint" pos="0 0 0" axis="0 1 0" range="-0.087267 2.8798" actuatorfrcrange="-139 139"/>
              <geom type="mesh" contype="0" conaffinity="0" group="1" density="0" rgba="0.7 0.7 0.7 1" mesh="left_knee_link"/>
              <geom type="mesh" rgba="0.7 0.7 0.7 1" mesh="left_knee_link"/>
              <body name="left_ankle_pitch_link" pos="0 -9.4445e-05 -0.30001">
                <inertial pos="-0.007269 0 0.011137" quat="0.603053 0.369225 0.369225 0.603053" mass="0.074" diaginertia="1.89e-05 1.40805e-05 6.9195e-06"/>
                <joint name="left_ankle_pitch_joint" pos="0 0 0" axis="0 1 0" range="-0.87267 0.5236" actuatorfrcrange="-50 50"/>
                <geom type="mesh" contype="0" conaffinity="0" group="1" density="0" rgba="0.7 0.7 0.7 1" mesh="left_ankle_pitch_link"/>
                <geom type="mesh" rgba="0.7 0.7 0.7 1" mesh="left_ankle_pitch_link"/>
                <body name="left_ankle_roll_link" pos="0 0 -0.017558">
                  <inertial pos="0.026505 0 -0.016425" quat="-0.000481092 0.728482 -0.000618967 0.685065" mass="0.608" diaginertia="0.00167218 0.0016161 0.000217621"/>
                  <joint name="left_ankle_roll_joint" pos="0 0 0" axis="1 0 0" range="-0.2618 0.2618" actuatorfrcrange="-50 50"/>
                  <geom type="mesh" contype="0" conaffinity="0" group="1" density="0" rgba="0.2 0.2 0.2 1" mesh="left_ankle_roll_link"/>
                  <geom size="0.005" pos="-0.05 0.025 -0.03" rgba="0.2 0.2 0.2 1"/>
                  <geom size="0.005" pos="-0.05 -0.025 -0.03" rgba="0.2 0.2 0.2 1"/>
                  <geom size="0.005" pos="0.12 0.03 -0.03" rgba="0.2 0.2 0.2 1"/>
                  <geom size="0.005" pos="0.12 -0.03 -0.03" rgba="0.2 0.2 0.2 1"/>
                </body>
              </body>
            </body>
          </body>
        </body>
      </body>

      <body name="right_hip_pitch_link" pos="0 -0.064452 -0.1027">
        <inertial pos="0.002741 -0.047791 -0.02606" quat="0.954862 -0.293964 0.0302556 -0.030122" mass="1.35" diaginertia="0.00181517 0.00153422 0.00116212"/>
        <joint name="right_hip_pitch_joint" pos="0 0 0" axis="0 1 0" range="-2.5307 2.8798" actuatorfrcrange="-88 88"/>
        <geom type="mesh" contype="0" conaffinity="0" group="1" density="0" rgba="0.2 0.2 0.2 1" mesh="right_hip_pitch_link"/>
        <geom type="mesh" rgba="0.2 0.2 0.2 1" mesh="right_hip_pitch_link"/>
        <body name="right_hip_roll_link" pos="0 -0.052 -0.030465" quat="0.996179 0 -0.0873386 0">
          <inertial pos="0.029812 0.001045 -0.087934" quat="0.977808 1.97119e-05 0.205576 0.0403793" mass="1.52" diaginertia="0.00254986 0.00241169 0.00148755"/>
          <joint name="right_hip_roll_joint" pos="0 0 0" axis="1 0 0" range="-2.9671 0.5236" actuatorfrcrange="-139 139"/>
          <geom type="mesh" contype="0" conaffinity="0" group="1" density="0" rgba="0.7 0.7 0.7 1" mesh="right_hip_roll_link"/>
          <geom type="mesh" rgba="0.7 0.7 0.7 1" mesh="right_hip_roll_link"/>
          <body name="right_hip_yaw_link" pos="0.025001 0 -0.12412">
            <inertial pos="-0.057709 0.010981 -0.15078" quat="0.751181 0.223482 0.15832 0.600598" mass="1.702" diaginertia="0.00776166 0.00717575 0.00160139"/>
            <joint name="right_hip_yaw_joint" pos="0 0 0" axis="0 0 1" range="-2.7576 2.7576" actuatorfrcrange="-88 88"/>
            <geom type="mesh" contype="0" conaffinity="0" group="1" density="0" rgba="0.7 0.7 0.7 1" mesh="right_hip_yaw_link"/>
            <geom type="mesh" rgba="0.7 0.7 0.7 1" mesh="right_hip_yaw_link"/>
            <body name="right_knee_link" pos="-0.078273 -0.0021489 -0.17734" quat="0.996179 0 0.0873386 0">
              <inertial pos="0.005457 -0.003964 -0.12074" quat="0.923439 0.0345276 0.0116333 -0.382012" mass="1.932" diaginertia="0.011374 0.0112843 0.00146452"/>
              <joint name="right_knee_joint" pos="0 0 0" axis="0 1 0" range="-0.087267 2.8798" actuatorfrcrange="-139 139"/>
              <geom type="mesh" contype="0" conaffinity="0" group="1" density="0" rgba="0.7 0.7 0.7 1" mesh="right_knee_link"/>
              <geom type="mesh" rgba="0.7 0.7 0.7 1" mesh="right_knee_link"/>
              <body name="right_ankle_pitch_link" pos="0 9.4445e-05 -0.30001">
                <inertial pos="-0.007269 0 0.011137" quat="0.603053 0.369225 0.369225 0.603053" mass="0.074" diaginertia="1.89e-05 1.40805e-05 6.9195e-06"/>
                <joint name="right_ankle_pitch_joint" pos="0 0 0" axis="0 1 0" range="-0.87267 0.5236" actuatorfrcrange="-50 50"/>
                <geom type="mesh" contype="0" conaffinity="0" group="1" density="0" rgba="0.7 0.7 0.7 1" mesh="right_ankle_pitch_link"/>
                <geom type="mesh" rgba="0.7 0.7 0.7 1" mesh="right_ankle_pitch_link"/>
                <body name="right_ankle_roll_link" pos="0 0 -0.017558">
                  <inertial pos="0.026505 0 -0.016425" quat="0.000481092 0.728482 0.000618967 0.685065" mass="0.608" diaginertia="0.00167218 0.0016161 0.000217621"/>
                  <joint name="right_ankle_roll_joint" pos="0 0 0" axis="1 0 0" range="-0.2618 0.2618" actuatorfrcrange="-50 50"/>
                  <geom type="mesh" contype="0" conaffinity="0" group="1" density="0" rgba="0.2 0.2 0.2 1" mesh="right_ankle_roll_link"/>
                  <geom size="0.005" pos="-0.05 0.025 -0.03" rgba="0.2 0.2 0.2 1"/>
                  <geom size="0.005" pos="-0.05 -0.025 -0.03" rgba="0.2 0.2 0.2 1"/>
                  <geom size="0.005" pos="0.12 0.03 -0.03" rgba="0.2 0.2 0.2 1"/>
                  <geom size="0.005" pos="0.12 -0.03 -0.03" rgba="0.2 0.2 0.2 1"/>
                </body>
              </body>
            </body>
          </body>
        </body>
      </body>
      <inertial pos="0.0144905 0.000151462 0.144068" quat="0.999881 -0.000505543 -0.0154276 0.000328408" mass="17.7349" diaginertia="0.552723 0.454092 0.211762"/>
      <joint name="floating_base_joint" type="free" limited="false" actuatorfrclimited="false"/>
      <geom type="mesh" contype="0" conaffinity="0" group="1" density="0" rgba="0.2 0.2 0.2 1" mesh="pelvis"/>
      <geom type="mesh" contype="0" conaffinity="0" group="1" density="0" rgba="0.7 0.7 0.7 1" mesh="pelvis_contour_link"/>
      <geom type="mesh" rgba="0.7 0.7 0.7 1" mesh="pelvis_contour_link"/>
      <geom type="mesh" contype="0" conaffinity="0" group="1" density="0" rgba="0.7 0.7 0.7 1" mesh="torso_link_23dof_rev_1_0"/>
      <geom type="mesh" rgba="0.7 0.7 0.7 1" mesh="torso_link_23dof_rev_1_0"/>
      <geom type="mesh" contype="0" conaffinity="0" group="1" density="0" rgba="0.2 0.2 0.2 1" mesh="logo_link"/>
      <geom type="mesh" rgba="0.2 0.2 0.2 1" mesh="logo_link"/>
      <geom type="mesh" contype="0" conaffinity="0" group="1" density="0" rgba="0.2 0.2 0.2 1" mesh="head_link"/>
      <geom type="mesh" rgba="0.2 0.2 0.2 1" mesh="head_link"/>

      <!-- ===== LEFT SHOULDER PITCH ===== -->
      <body name="left_shoulder_pitch" pos="7.72569e-07 0.141427 0.293195">
        <!-- pitch вокруг Y -->
        <joint name="left_shoulder_pitch_joint" type="hinge" pos="0 0 0" axis="0 1 0"
              range="-3.0892 2.6704" actuatorfrcrange="-25 25"/>
        <geom type="cylinder" size="0.03 0.025" pos="0 0 0" rgba="0.7 0.7 0.7 1"/>

        <!-- геом pitch -->
        <geom type="mesh" mesh="left_shoulder_pitch_link"
              pos="-7.972569e-06 -0.041207 -0.001415"
              quat="0.990264 0.139201 1.38722e-05 -9.86868e-05"
              contype="0" conaffinity="0" density="0" rgba="0.7 0.7 0.7 1"/>

        <!-- roll вокруг X -->
        <body name="left_shoulder_roll" pos="0 0 0">
          <!-- ваша «заглушка» инерции для предотвращения нулевой массы -->
          <inertial pos="0 0 0" quat="1 0 0 0" mass="0.6" diaginertia="0.0012 0.0010 0.0008"/>
          <joint name="left_shoulder_roll_joint" type="hinge" pos="0 0 0" axis="1 0 0"
                range="-2.356 2.356" actuatorfrcrange="-80 80"/>

          <geom type="mesh" mesh="left_shoulder_roll_link"
                pos="-3.98627e-07 -0.000867 -0.004234"
                quat="1 3.00026e-05 2.74716e-05 -9.57958e-05"
                contype="0" conaffinity="0" density="0" rgba="0.7 0.7 0.7 1"/>

          <!-- НОВОЕ: yaw вокруг Z -->
          <body name="left_shoulder_yaw" pos="0 0 0">
            <!-- ненулевая инерция yaw (взята близко к детальной модели) -->
            <inertial pos="0 0 0" quat="1 0 0 0"
                      mass="0.734" diaginertia="0.00106187 0.00103217 0.000400661"/>
            <joint name="left_shoulder_yaw_joint" type="hinge" pos="0 0 0" axis="0 0 1"
                  range="-2.618 2.618" actuatorfrcrange="-80 80"/>

            <!-- геом yaw -->
            <geom type="mesh" mesh="left_shoulder_yaw_link"
                  pos="-4.872639e-06 0.00538 -0.107433"
                  quat="1 3.00026e-05 2.74716e-05 -9.57958e-05"
                  contype="0" conaffinity="0" density="0" rgba="0.7 0.7 0.7 1"/>

            <body name="left_elbow_link" pos="0.015773727 0.005381 -0.187952">
              <!-- инерция локтя (как было) -->
              <inertial pos="0.064956 0.004454 -0.010062"
                        quat="0.541765 0.636132 0.388821 0.388129"
                        mass="0.6"
                        diaginertia="0.000443035 0.000421612 0.000259353"/>
              <joint name="left_elbow_joint" pos="0 0 0" axis="0 1 0"
                    range="-1.0472 2.0944" actuatorfrcrange="-25 25"/>

              <!-- геом локтя как визуал -->
              <geom type="mesh" mesh="left_elbow_link"
                    quat="1 3.00026e-05 2.74716e-05 -9.57958e-05"
                    contype="0" conaffinity="0" density="0" rgba="0.7 0.7 0.7 1"/>

              <!-- ========== LEFT HAND (collision) ========== -->
        <!-- === LEFT HAND: wrist(roll→pitch→yaw) + palm + 3 пальца === --> <body name="left_wrist_roll_link" pos="0.1 0.00188791 -0.01"> <inertial pos="0.0171394 0.000537591 4.8864e-07" quat="0.575338 0.411667 -0.574906 0.411094" mass="0.085445" diaginertia="5.48211e-05 4.96646e-05 3.57798e-05"/> <joint name="left_wrist_roll_joint" type="hinge" axis="1 0 0" range="-1.97222 1.97222"/> <geom type="mesh" mesh="left_wrist_roll_link" density="0" contype="0" conaffinity="0" rgba="0.7 0.7 0.7 1"/> <body name="left_wrist_pitch_link" pos="0.038 0 0"> <inertial pos="0.0229999 -0.00111685 -0.00111658" quat="0.249998 0.661363 0.293036 0.643608" mass="0.48405" diaginertia="0.000430353 0.000429873 0.000164648"/> <joint name="left_wrist_pitch_joint" type="hinge" axis="0 1 0" range="-1.61443 1.61443"/> <geom type="mesh" mesh="left_wrist_pitch_link" density="0" contype="0" conaffinity="0" rgba="0.7 0.7 0.7 1"/>
<body name="left_wrist_yaw_link" pos="0.046 0 0">
  <inertial pos="0.0885506 0.00212216 -0.000374562" quat="0.487149 0.493844 0.513241 0.505358" mass="0.457415" diaginertia="0.00105989 0.000895419 0.000323842"/>
  <joint name="left_wrist_yaw_joint" type="hinge" axis="0 0 1" range="-1.61443 1.61443"/>
  <geom type="mesh" mesh="left_wrist_yaw_link" density="0" contype="0" conaffinity="0" rgba="0.7 0.7 0.7 1"/>

  <!-- PALM: визуал + коллизия -->
  <geom type="mesh" mesh="left_hand_palm_link" pos="0.0415 0.003 0" density="0" contype="0" conaffinity="0" rgba="0.7 0.7 0.7 1"/>
  <geom name="l_palm_col" type="box" pos="0.0415 0.003 0" size="0.030 0.022 0.012"
        contype="1" conaffinity="1" condim="4"
        friction="1.2 0.02 0.001" solref="0.004 1" solimp="0.95 0.99 0.002"/>

  <!-- THUMB (3 фаланги) -->
  <body name="left_hand_thumb_0_link" pos="0.0882 0.0135 0">
    <inertial pos="-0.000884246 -0.00863407 0.000944293" quat="0.462991 0.643965 -0.460173 0.398986" mass="0.0862366" diaginertia="1.6546e-05 1.60058e-05 1.43741e-05"/>
    <joint name="left_hand_thumb_0_joint" type="hinge" axis="0 1 0" range="-1.22173 1.22173"/>
    <geom type="mesh" mesh="left_hand_thumb_0_link" density="0" contype="0" conaffinity="0" rgba="0.7 0.7 0.7 1"/>
    <geom name="l_thumb0_col" type="capsule" fromto="0 0 0 0.018 0 0" size="0.008" contype="1" conaffinity="1" condim="4"/>

    <body name="left_hand_thumb_1_link" pos="-0.0025 -0.0193 0">
      <inertial pos="-0.000827888 -0.0354744 -0.0003809" quat="0.685598 0.705471 -0.15207 0.0956069" mass="0.0588507" diaginertia="1.28514e-05 1.22902e-05 5.9666e-06"/>
      <joint name="left_hand_thumb_1_joint" type="hinge" axis="0 0 1" range="-1.0472 1.0472"/>
      <geom type="mesh" mesh="left_hand_thumb_1_link" density="0" contype="0" conaffinity="0" rgba="0.7 0.7 0.7 1"/>
      <geom name="l_thumb1_col" type="capsule" fromto="0 0 0 0.018 0 0" size="0.007" contype="1" conaffinity="1" condim="4"/>

      <body name="left_hand_thumb_2_link" pos="0 -0.0458 0">
        <inertial pos="-0.00171735 -0.0262819 0.000107789" quat="0.703174 0.710977 -0.00017564 -0.00766553" mass="0.0203063" diaginertia="4.61314e-06 3.86645e-06 1.53495e-06"/>
        <joint name="left_hand_thumb_2_joint" type="hinge" axis="0 0 1" range="-1.0472 1.0472"/>
        <geom type="mesh" mesh="left_hand_thumb_2_link" density="0" contype="0" conaffinity="0" rgba="0.7 0.7 0.7 1"/>
        <geom name="l_thumb2_col" type="capsule" fromto="0 0 0 0.016 0 0" size="0.006" contype="1" conaffinity="1" condim="4"/>
      </body>
    </body>
  </body>

  <!-- MIDDLE (2 фаланги) -->
  <body name="left_hand_middle_0_link" pos="0.1192 0.0046 -0.0285">
    <inertial pos="0.0354744 0.000827888 0.0003809" quat="0.391313 0.552395 0.417187 0.606373" mass="0.0588507" diaginertia="1.28514e-05 1.22902e-05 5.9666e-06"/>
    <joint name="left_hand_middle_0_joint" type="hinge" axis="0 0 1" range="-1.74533 0"/>
    <geom type="mesh" mesh="left_hand_middle_0_link" density="0" contype="0" conaffinity="0" rgba="0.7 0.7 0.7 1"/>
    <geom name="l_mid0_col" type="capsule" fromto="0 0 0 0.022 0 0" size="0.007" contype="1" conaffinity="1" condim="4"/>

    <body name="left_hand_middle_1_link" pos="0.0458 0 0">
      <inertial pos="0.0262819 0.00171735 -0.000107789" quat="0.502612 0.491799 0.502639 0.502861" mass="0.0203063" diaginertia="4.61314e-06 3.86645e-06 1.53495e-06"/>
      <joint name="left_hand_middle_1_joint" type="hinge" axis="0 0 1" range="-1.5708 0"/>
      <geom type="mesh" mesh="left_hand_middle_1_link" density="0" contype="0" conaffinity="0" rgba="0.7 0.7 0.7 1"/>
      <geom name="l_mid1_col" type="capsule" fromto="0 0 0 0.022 0 0" size="0.006" contype="1" conaffinity="1" condim="4"/>
    </body>
  </body>

  <!-- INDEX (2 фаланги) -->
  <body name="left_hand_index_0_link" pos="0.1192 0.0046 0.0285">
    <inertial pos="0.0354744 0.000827888 0.0003809" quat="0.391313 0.552395 0.417187 0.606373" mass="0.0588507" diaginertia="1.28514e-05 1.22902e-05 5.9666e-06"/>
    <joint name="left_hand_index_0_joint" type="hinge" axis="0 0 1" range="-1.74533 0"/>
    <geom type="mesh" mesh="left_hand_index_0_link" density="0" contype="0" conaffinity="0" rgba="0.7 0.7 0.7 1"/>
    <geom name="l_ind0_col" type="capsule" fromto="0 0 0 0.022 0 0" size="0.007" contype="1" conaffinity="1" condim="4"/>

    <body name="left_hand_index_1_link" pos="0.0458 0 0">
      <inertial pos="0.0262819 0.00171735 -0.000107789" quat="0.502612 0.491799 0.502639 0.502861" mass="0.0203063" diaginertia="4.61314e-06 3.86645e-06 1.53495e-06"/>
      <joint name="left_hand_index_1_joint" type="hinge" axis="0 0 1" range="-1.5708 0"/>
      <geom type="mesh" mesh="left_hand_index_1_link" density="0" contype="0" conaffinity="0" rgba="0.7 0.7 0.7 1"/>
      <geom name="l_ind1_col" type="capsule" fromto="0 0 0 0.020 0 0" size="0.006" contype="1" conaffinity="1" condim="4"/>
    </body>
  </body>

</body>

</body> </body> <!-- === /LEFT HAND === -->


             

            </body>


          </body>
        </body>
      </body>
      <!-- ===== /LEFT SHOULDER PITCH ===== -->


    <!-- ===== RIGHT SHOULDER PITCH ===== -->
    <body name="right_shoulder_pitch" pos="7.72569e-07 -0.141417 0.293195">
      <!-- pitch вокруг Y -->
      <joint name="right_shoulder_pitch_joint" type="hinge" pos="0 0 0" axis="0 1 0"
            range="-3.0892 2.6704" actuatorfrcrange="-25 25"/>
      <geom type="cylinder" size="0.03 0.025" pos="0 0 0" rgba="0.7 0.7 0.7 1"/>

      <geom type="mesh" mesh="right_shoulder_pitch_link"
            pos="-7.972569e-06 0.041207 -0.001415"
            quat="0.990264 -0.139201 1.38722e-05 9.86868e-05"
            contype="0" conaffinity="0" density="0" rgba="0.7 0.7 0.7 1"/>

      <!-- roll вокруг X -->
      <body name="right_shoulder_roll" pos="0 0 0">
        <inertial pos="0 0 0" quat="1 0 0 0" mass="0.6" diaginertia="0.0012 0.0010 0.0008"/>
        <joint name="right_shoulder_roll_joint" type="hinge" pos="0 0 0" axis="1 0 0"
              range="-2.356 2.356" actuatorfrcrange="-80 80"/>

        <geom type="mesh" mesh="right_shoulder_roll_link"
              pos="-3.98627e-07 0.000867 -0.004234"
              quat="1 -3.00026e-05 2.74716e-05 9.57958e-05"
              contype="0" conaffinity="0" density="0" rgba="0.7 0.7 0.7 1"/>

        <!-- НОВОЕ: yaw вокруг Z -->
        <body name="right_shoulder_yaw" pos="0 0 0">
          <inertial pos="0 0 0" quat="1 0 0 0"
                    mass="0.734" diaginertia="0.00106187 0.00103217 0.000400661"/>
          <joint name="right_shoulder_yaw_joint" type="hinge" pos="0 0 0" axis="0 0 1"
                range="-2.618 2.618" actuatorfrcrange="-80 80"/>

          <geom type="mesh" mesh="right_shoulder_yaw_link"
                pos="-4.872639e-06 -0.00538 -0.107433"
                quat="1 -3.00026e-05 2.74716e-05 9.57958e-05"
                contype="0" conaffinity="0" density="0" rgba="0.7 0.7 0.7 1"/>

                    <!-- elbow joint + link -->
          <body name="right_elbow_link" pos="0.015773727 -0.005381 -0.187952">
            <!-- инерция локтя как в 29-DoF -->
            <inertial pos="0.064956 -0.004454 -0.010062"
                      quat="0.388129 0.388821 0.636132 0.541765"
                      mass="0.6"
                      diaginertia="0.000443035 0.000421612 0.000259353"/>
            <!-- шарнир локтя как в 29-DoF: ось Y -->
            <joint name="right_elbow_joint" pos="0 0 0" axis="0 1 0"
                  range="-1.0472 2.0944" actuatorfrcrange="-25 25"/>

         <!-- ВИЗУАЛ предплечья остаётся -->
            <geom type="mesh" mesh="right_elbow_link"
                  quat="1 -3.00026e-05 2.74716e-05 9.57958e-05"
                  contype="0" conaffinity="0" density="0" rgba="0.7 0.7 0.7 1"/>

       <!-- === RIGHT HAND: wrist(roll→pitch→yaw) + palm + 3 пальца === -->
<!-- === RIGHT HAND: wrist(roll→pitch→yaw) + palm + 3 пальца === --> <body name="right_wrist_roll_link" pos="0.1 -0.00188791 -0.01"> <inertial pos="0.0171394 -0.000537591 4.8864e-07" quat="0.411667 0.575338 -0.411094 0.574906" mass="0.085445" diaginertia="5.48211e-05 4.96646e-05 3.57798e-05"/> <joint name="right_wrist_roll_joint" type="hinge" axis="1 0 0" range="-1.97222 1.97222"/> <geom type="mesh" mesh="right_wrist_roll_link" density="0" contype="0" conaffinity="0" rgba="0.7 0.7 0.7 1"/> <body name="right_wrist_pitch_link" pos="0.038 0 0"> <inertial pos="0.0229999 0.00111685 -0.00111658" quat="0.643608 0.293036 0.661363 0.249998" mass="0.48405" diaginertia="0.000430353 0.000429873 0.000164648"/> <joint name="right_wrist_pitch_joint" type="hinge" axis="0 1 0" range="-1.61443 1.61443"/> <geom type="mesh" mesh="right_wrist_pitch_link" density="0" contype="0" conaffinity="0" rgba="0.7 0.7 0.7 1"/>
<body name="right_wrist_yaw_link" pos="0.046 0 0">
  <inertial pos="0.0885506 -0.00212216 -0.000374562" quat="0.505358 0.513241 0.493844 0.487149" mass="0.457415" diaginertia="0.00105989 0.000895419 0.000323842"/>
  <joint name="right_wrist_yaw_joint" type="hinge" axis="0 0 1" range="-1.61443 1.61443"/>
  <geom type="mesh" mesh="right_wrist_yaw_link" density="0" contype="0" conaffinity="0" rgba="0.7 0.7 0.7 1"/>

  <!-- PALM -->
  <geom type="mesh" mesh="right_hand_palm_link" pos="0.0415 -0.003 0" density="0" contype="0" conaffinity="0" rgba="0.7 0.7 0.7 1"/>
  <geom name="r_palm_col" type="box" pos="0.0415 -0.003 0" size="0.030 0.022 0.012"
        contype="1" conaffinity="1" condim="4"
        friction="1.2 0.02 0.001" solref="0.004 1" solimp="0.95 0.99 0.002"/>

  <!-- THUMB -->
  <body name="right_hand_thumb_0_link" pos="0.0882 -0.0135 0">
    <inertial pos="-0.000884246 0.00863407 0.000944293" quat="0.643965 0.462991 -0.398986 0.460173" mass="0.0862366" diaginertia="1.6546e-05 1.60058e-05 1.43741e-05"/>
    <joint name="right_hand_thumb_0_joint" type="hinge" axis="0 -1 0" range="-1.22173 1.22173"/>
    <geom type="mesh" mesh="right_hand_thumb_0_link" density="0" contype="0" conaffinity="0" rgba="0.7 0.7 0.7 1"/>
    <geom name="r_thumb0_col" type="capsule" fromto="0 0 0 0.018 0 0" size="0.008" contype="1" conaffinity="1" condim="4"/>

    <body name="right_hand_thumb_1_link" pos="-0.0025 0.0193 0">
      <inertial pos="-0.000827888 0.0354744 -0.0003809" quat="0.705471 0.685598 -0.0956069 0.15207" mass="0.0588507" diaginertia="1.28514e-05 1.22902e-05 5.9666e-06"/>
      <joint name="right_hand_thumb_1_joint" type="hinge" axis="0 0 1" range="-1.0472 1.0472"/>
      <geom type="mesh" mesh="right_hand_thumb_1_link" density="0" contype="0" conaffinity="0" rgba="0.7 0.7 0.7 1"/>
      <geom name="r_thumb1_col" type="capsule" fromto="0 0 0 0.018 0 0" size="0.007" contype="1" conaffinity="1" condim="4"/>

      <body name="right_hand_thumb_2_link" pos="0 0.0458 0">
        <inertial pos="-0.00171735 0.0262819 0.000107789" quat="0.710977 0.703174 0.00766553 0.00017564" mass="0.0203063" diaginertia="4.61314e-06 3.86645e-06 1.53495e-06"/>
        <joint name="right_hand_thumb_2_joint" type="hinge" axis="0 0 1" range="-1.0472 1.0472"/>
        <geom type="mesh" mesh="right_hand_thumb_2_link" density="0" contype="0" conaffinity="0" rgba="0.7 0.7 0.7 1"/>
        <geom name="r_thumb2_col" type="capsule" fromto="0 0 0 0.016 0 0" size="0.006" contype="1" conaffinity="1" condim="4"/>
      </body>
    </body>
  </body>

  <!-- MIDDLE -->
  <body name="right_hand_middle_0_link" pos="0.1192 -0.0046 -0.0285">
    <inertial pos="0.0354744 -0.000827888 0.0003809" quat="0.606373 0.417187 0.552395 0.391313" mass="0.0588507" diaginertia="1.28514e-05 1.22902e-05 5.9666e-06"/>
    <joint name="right_hand_middle_0_joint" type="hinge" axis="0 0 1" range="-1.5708 0"/>
    <geom type="mesh" mesh="right_hand_middle_0_link" density="0" contype="0" conaffinity="0" rgba="0.7 0.7 0.7 1"/>
    <geom name="r_mid0_col" type="capsule" fromto="0 0 0 0.022 0 0" size="0.007" contype="1" conaffinity="1" condim="4"/>

    <body name="right_hand_middle_1_link" pos="0.0458 0 0">
      <inertial pos="0.0262819 -0.00171735 -0.000107789" quat="0.502861 0.502639 0.491799 0.502612" mass="0.0203063" diaginertia="4.61314e-06 3.86645e-06 1.53495e-06"/>
      <joint name="right_hand_middle_1_joint" type="hinge" axis="0 0 1" range="-1.5708 0"/>
      <geom type="mesh" mesh="right_hand_middle_1_link" density="0" contype="0" conaffinity="0" rgba="0.7 0.7 0.7 1"/>
      <geom name="r_mid1_col" type="capsule" fromto="0 0 0 0.022 0 0" size="0.006" contype="1" conaffinity="1" condim="4"/>
    </body>
  </body>

  <!-- INDEX -->
  <body name="right_hand_index_0_link" pos="0.1192 -0.0046 0.0285">
    <inertial pos="0.0354744 -0.000827888 0.0003809" quat="0.606373 0.417187 0.552395 0.391313" mass="0.0588507" diaginertia="1.28514e-05 1.22902e-05 5.9666e-06"/>
    <joint name="right_hand_index_0_joint" type="hinge" axis="0 0 1" range="-1.5708 0"/>
    <geom type="mesh" mesh="right_hand_index_0_link" density="0" contype="0" conaffinity="0" rgba="0.7 0.7 0.7 1"/>
    <geom name="r_ind0_col" type="capsule" fromto="0 0 0 0.022 0 0" size="0.007" contype="1" conaffinity="1" condim="4"/>

    <body name="right_hand_index_1_link" pos="0.0458 0 0">
      <inertial pos="0.0262819 -0.00171735 -0.000107789" quat="0.502861 0.502639 0.491799 0.502612" mass="0.0203063" diaginertia="4.61314e-06 3.86645e-06 1.53495e-06"/>
      <joint name="right_hand_index_1_joint" type="hinge" axis="0 0 1" range="-1.5708 0"/>
      <geom type="mesh" mesh="right_hand_index_1_link" density="0" contype="0" conaffinity="0" rgba="0.7 0.7 0.7 1"/>
      <geom name="r_ind1_col" type="capsule" fromto="0 0 0 0.020 0 0" size="0.006" contype="1" conaffinity="1" condim="4"/>
    </body>
  </body>

</body>

</body> </body> <!-- === /RIGHT HAND === -->



          </body>      
          

        </body>
      </body>
    </body>
    <!-- ===== /RIGHT SHOULDER PITCH ===== -->


      
    </body>
  </worldbody>

  <actuator>
    <!-- Двигатель для управляемого pitch плеча -->
    

    <!-- Ноги как были -->
    <motor name="left_hip_pitch_joint" joint="left_hip_pitch_joint"/>
    <motor name="left_hip_roll_joint" joint="left_hip_roll_joint"/>
    <motor name="left_hip_yaw_joint" joint="left_hip_yaw_joint"/>
    <motor name="left_knee_joint" joint="left_knee_joint"/>
    <motor name="left_ankle_pitch_joint" joint="left_ankle_pitch_joint"/>
    <motor name="left_ankle_roll_joint" joint="left_ankle_roll_joint"/>
    <motor name="right_hip_pitch_joint" joint="right_hip_pitch_joint"/>
    <motor name="right_hip_roll_joint" joint="right_hip_roll_joint"/>
    <motor name="right_hip_yaw_joint" joint="right_hip_yaw_joint"/>
    <motor name="right_knee_joint" joint="right_knee_joint"/>
    <motor name="right_ankle_pitch_joint" joint="right_ankle_pitch_joint"/>
    <motor name="right_ankle_roll_joint" joint="right_ankle_roll_joint"/>

<!-- ЛЕВАЯ РУКА -->
<motor joint="left_shoulder_pitch_joint" gear="60" ctrlrange="-1 1"/>
<motor joint="left_shoulder_roll_joint"  gear="60" ctrlrange="-1 1"/>
<motor joint="left_shoulder_yaw_joint"   gear="60" ctrlrange="-1 1"/>
<motor joint="left_elbow_joint"          gear="50" ctrlrange="-1 1"/>

<!-- ПРАВАЯ РУКА -->
<motor joint="right_shoulder_pitch_joint" gear="60" ctrlrange="-1 1"/>
<motor joint="right_shoulder_roll_joint"  gear="60" ctrlrange="-1 1"/>
<motor joint="right_shoulder_yaw_joint"   gear="60" ctrlrange="-1 1"/>
<motor joint="right_elbow_joint"          gear="50" ctrlrange="-1 1"/>

 

  </actuator>
  <!-- === ACTUATORS: LEFT HAND === -->
<actuator>
  <!-- запястье -->
  <motor name="left_wrist_roll_joint"  joint="left_wrist_roll_joint"  gear="1" ctrlrange="-6 6"/>
  <motor name="left_wrist_pitch_joint" joint="left_wrist_pitch_joint" gear="1" ctrlrange="-6 6"/>
  <motor name="left_wrist_yaw_joint"   joint="left_wrist_yaw_joint"   gear="1" ctrlrange="-6 6"/>

  <!-- большой палец -->
  <motor name="left_hand_thumb_0_joint" joint="left_hand_thumb_0_joint" gear="1" ctrlrange="-3 3"/>
  <motor name="left_hand_thumb_1_joint" joint="left_hand_thumb_1_joint" gear="1" ctrlrange="-3 3"/>
  <motor name="left_hand_thumb_2_joint" joint="left_hand_thumb_2_joint" gear="1" ctrlrange="-3 3"/>

  <!-- средний -->
  <motor name="left_hand_middle_0_joint" joint="left_hand_middle_0_joint" gear="1" ctrlrange="-3 3"/>
  <motor name="left_hand_middle_1_joint" joint="left_hand_middle_1_joint" gear="1" ctrlrange="-3 3"/>

  <!-- указательный -->
  <motor name="left_hand_index_0_joint" joint="left_hand_index_0_joint" gear="1" ctrlrange="-3 3"/>
  <motor name="left_hand_index_1_joint" joint="left_hand_index_1_joint" gear="1" ctrlrange="-3 3"/>
</actuator>

<!-- === ACTUATORS: RIGHT HAND === -->
<actuator>
  <motor name="right_wrist_roll_joint"  joint="right_wrist_roll_joint"  gear="1" ctrlrange="-6 6"/>
  <motor name="right_wrist_pitch_joint" joint="right_wrist_pitch_joint" gear="1" ctrlrange="-6 6"/>
  <motor name="right_wrist_yaw_joint"   joint="right_wrist_yaw_joint"   gear="1" ctrlrange="-6 6"/>

  <motor name="right_hand_thumb_0_joint" joint="right_hand_thumb_0_joint" gear="1" ctrlrange="-3 3"/>
  <motor name="right_hand_thumb_1_joint" joint="right_hand_thumb_1_joint" gear="1" ctrlrange="-3 3"/>
  <motor name="right_hand_thumb_2_joint" joint="right_hand_thumb_2_joint" gear="1" ctrlrange="-3 3"/>

  <motor name="right_hand_middle_0_joint" joint="right_hand_middle_0_joint" gear="1" ctrlrange="-3 3"/>
  <motor name="right_hand_middle_1_joint" joint="right_hand_middle_1_joint" gear="1" ctrlrange="-3 3"/>

  <motor name="right_hand_index_0_joint" joint="right_hand_index_0_joint" gear="1" ctrlrange="-3 3"/>
  <motor name="right_hand_index_1_joint" joint="right_hand_index_1_joint" gear="1" ctrlrange="-3 3"/>
</actuator>

</mujoco>
